2020/03/29 11:00:37 ERROR [django:30444:hello error]
2020/03/29 11:04:47 ERROR [django:30444:hello error]
2020/03/29 11:32:59 ERROR [django:30443:hello error]
2020/04/01 14:35:34 ERROR [django:30444:hello error]
2020/04/01 15:54:49 ERROR [django.request:6012:Internal Server Error: /django/world/]
Traceback (most recent call last):
  File "/home/Student/djangoproject/myvenv/lib/python3.5/site-packages/django/core/handlers/exception.py", line 34, in inner
    response = get_response(request)
  File "/home/Student/djangoproject/myvenv/lib/python3.5/site-packages/django/core/handlers/base.py", line 115, in _get_response
    response = self.process_exception_by_middleware(e, request)
  File "/home/Student/djangoproject/myvenv/lib/python3.5/site-packages/django/core/handlers/base.py", line 113, in _get_response
    response = wrapped_callback(request, *callback_args, **callback_kwargs)
  File "/home/Student/djangoproject/bestproject/bookshop/views.py", line 19, in world
    return render(request, './bookshop/index.html', response)
  File "/home/Student/djangoproject/myvenv/lib/python3.5/site-packages/django/shortcuts.py", line 36, in render
    content = loader.render_to_string(template_name, context, request, using=using)
  File "/home/Student/djangoproject/myvenv/lib/python3.5/site-packages/django/template/loader.py", line 62, in render_to_string
    return template.render(context, request)
  File "/home/Student/djangoproject/myvenv/lib/python3.5/site-packages/django/template/backends/django.py", line 61, in render
    return self.template.render(context)
  File "/home/Student/djangoproject/myvenv/lib/python3.5/site-packages/django/template/base.py", line 171, in render
    return self._render(context)
  File "/home/Student/djangoproject/myvenv/lib/python3.5/site-packages/django/template/base.py", line 163, in _render
    return self.nodelist.render(context)
  File "/home/Student/djangoproject/myvenv/lib/python3.5/site-packages/django/template/base.py", line 937, in render
    bit = node.render_annotated(context)
  File "/home/Student/djangoproject/myvenv/lib/python3.5/site-packages/django/template/base.py", line 904, in render_annotated
    return self.render(context)
  File "/home/Student/djangoproject/myvenv/lib/python3.5/site-packages/django/template/defaulttags.py", line 443, in render
    url = reverse(view_name, args=args, kwargs=kwargs, current_app=current_app)
  File "/home/Student/djangoproject/myvenv/lib/python3.5/site-packages/django/urls/base.py", line 90, in reverse
    return iri_to_uri(resolver._reverse_with_prefix(view, prefix, *args, **kwargs))
  File "/home/Student/djangoproject/myvenv/lib/python3.5/site-packages/django/urls/resolvers.py", line 673, in _reverse_with_prefix
    raise NoReverseMatch(msg)
django.urls.exceptions.NoReverseMatch: Reverse for 'comment_url' not found. 'comment_url' is not a valid view function or pattern name.
2020/04/01 18:34:55 ERROR [django:8511:hello error]
2020/04/01 19:30:29 ERROR [django.request:9878:Internal Server Error: /django/admin/bookshop/comment/]
Traceback (most recent call last):
  File "/home/Student/djangoproject/myvenv/lib/python3.5/site-packages/django/db/models/options.py", line 565, in get_field
    return self.fields_map[field_name]
KeyError: '__str__'

During handling of the above exception, another exception occurred:

Traceback (most recent call last):
  File "/home/Student/djangoproject/myvenv/lib/python3.5/site-packages/django/contrib/admin/utils.py", line 262, in lookup_field
    f = _get_non_gfk_field(opts, name)
  File "/home/Student/djangoproject/myvenv/lib/python3.5/site-packages/django/contrib/admin/utils.py", line 293, in _get_non_gfk_field
    field = opts.get_field(name)
  File "/home/Student/djangoproject/myvenv/lib/python3.5/site-packages/django/db/models/options.py", line 567, in get_field
    raise FieldDoesNotExist("%s has no field named '%s'" % (self.object_name, field_name))
django.core.exceptions.FieldDoesNotExist: Comment has no field named '__str__'

During handling of the above exception, another exception occurred:

Traceback (most recent call last):
  File "/home/Student/djangoproject/myvenv/lib/python3.5/site-packages/django/core/handlers/exception.py", line 34, in inner
    response = get_response(request)
  File "/home/Student/djangoproject/myvenv/lib/python3.5/site-packages/django/core/handlers/base.py", line 145, in _get_response
    response = self.process_exception_by_middleware(e, request)
  File "/home/Student/djangoproject/myvenv/lib/python3.5/site-packages/django/core/handlers/base.py", line 143, in _get_response
    response = response.render()
  File "/home/Student/djangoproject/myvenv/lib/python3.5/site-packages/django/template/response.py", line 106, in render
    self.content = self.rendered_content
  File "/home/Student/djangoproject/myvenv/lib/python3.5/site-packages/django/template/response.py", line 83, in rendered_content
    content = template.render(context, self._request)
  File "/home/Student/djangoproject/myvenv/lib/python3.5/site-packages/django/template/backends/django.py", line 61, in render
    return self.template.render(context)
  File "/home/Student/djangoproject/myvenv/lib/python3.5/site-packages/django/template/base.py", line 171, in render
    return self._render(context)
  File "/home/Student/djangoproject/myvenv/lib/python3.5/site-packages/django/template/base.py", line 163, in _render
    return self.nodelist.render(context)
  File "/home/Student/djangoproject/myvenv/lib/python3.5/site-packages/django/template/base.py", line 937, in render
    bit = node.render_annotated(context)
  File "/home/Student/djangoproject/myvenv/lib/python3.5/site-packages/django/template/base.py", line 904, in render_annotated
    return self.render(context)
  File "/home/Student/djangoproject/myvenv/lib/python3.5/site-packages/django/template/loader_tags.py", line 150, in render
    return compiled_parent._render(context)
  File "/home/Student/djangoproject/myvenv/lib/python3.5/site-packages/django/template/base.py", line 163, in _render
    return self.nodelist.render(context)
  File "/home/Student/djangoproject/myvenv/lib/python3.5/site-packages/django/template/base.py", line 937, in render
    bit = node.render_annotated(context)
  File "/home/Student/djangoproject/myvenv/lib/python3.5/site-packages/django/template/base.py", line 904, in render_annotated
    return self.render(context)
  File "/home/Student/djangoproject/myvenv/lib/python3.5/site-packages/django/template/loader_tags.py", line 150, in render
    return compiled_parent._render(context)
  File "/home/Student/djangoproject/myvenv/lib/python3.5/site-packages/django/template/base.py", line 163, in _render
    return self.nodelist.render(context)
  File "/home/Student/djangoproject/myvenv/lib/python3.5/site-packages/django/template/base.py", line 937, in render
    bit = node.render_annotated(context)
  File "/home/Student/djangoproject/myvenv/lib/python3.5/site-packages/django/template/base.py", line 904, in render_annotated
    return self.render(context)
  File "/home/Student/djangoproject/myvenv/lib/python3.5/site-packages/django/template/loader_tags.py", line 62, in render
    result = block.nodelist.render(context)
  File "/home/Student/djangoproject/myvenv/lib/python3.5/site-packages/django/template/base.py", line 937, in render
    bit = node.render_annotated(context)
  File "/home/Student/djangoproject/myvenv/lib/python3.5/site-packages/django/template/base.py", line 904, in render_annotated
    return self.render(context)
  File "/home/Student/djangoproject/myvenv/lib/python3.5/site-packages/django/template/loader_tags.py", line 62, in render
    result = block.nodelist.render(context)
  File "/home/Student/djangoproject/myvenv/lib/python3.5/site-packages/django/template/base.py", line 937, in render
    bit = node.render_annotated(context)
  File "/home/Student/djangoproject/myvenv/lib/python3.5/site-packages/django/template/base.py", line 904, in render_annotated
    return self.render(context)
  File "/home/Student/djangoproject/myvenv/lib/python3.5/site-packages/django/contrib/admin/templatetags/base.py", line 33, in render
    return super().render(context)
  File "/home/Student/djangoproject/myvenv/lib/python3.5/site-packages/django/template/library.py", line 214, in render
    _dict = self.func(*resolved_args, **resolved_kwargs)
  File "/home/Student/djangoproject/myvenv/lib/python3.5/site-packages/django/contrib/admin/templatetags/admin_list.py", line 339, in result_list
    'results': list(results(cl)),
  File "/home/Student/djangoproject/myvenv/lib/python3.5/site-packages/django/contrib/admin/templatetags/admin_list.py", line 315, in results
    yield ResultList(None, items_for_result(cl, res, None))
  File "/home/Student/djangoproject/myvenv/lib/python3.5/site-packages/django/contrib/admin/templatetags/admin_list.py", line 306, in __init__
    super().__init__(*items)
  File "/home/Student/djangoproject/myvenv/lib/python3.5/site-packages/django/contrib/admin/templatetags/admin_list.py", line 229, in items_for_result
    f, attr, value = lookup_field(field_name, result, cl.model_admin)
  File "/home/Student/djangoproject/myvenv/lib/python3.5/site-packages/django/contrib/admin/utils.py", line 275, in lookup_field
    value = attr()
  File "/home/Student/djangoproject/bestproject/bookshop/models.py", line 61, in __str__
    return str(self.id) + elf.text[:10] + "..."
NameError: name 'elf' is not defined
2020/04/01 19:39:16 ERROR [django.request:10045:Internal Server Error: /django/world/]
Traceback (most recent call last):
  File "/home/Student/djangoproject/myvenv/lib/python3.5/site-packages/django/core/handlers/exception.py", line 34, in inner
    response = get_response(request)
  File "/home/Student/djangoproject/myvenv/lib/python3.5/site-packages/django/core/handlers/base.py", line 115, in _get_response
    response = self.process_exception_by_middleware(e, request)
  File "/home/Student/djangoproject/myvenv/lib/python3.5/site-packages/django/core/handlers/base.py", line 113, in _get_response
    response = wrapped_callback(request, *callback_args, **callback_kwargs)
  File "/home/Student/djangoproject/bestproject/bookshop/views.py", line 19, in world
    return render(request, './bookshop/index.html', response)
  File "/home/Student/djangoproject/myvenv/lib/python3.5/site-packages/django/shortcuts.py", line 36, in render
    content = loader.render_to_string(template_name, context, request, using=using)
  File "/home/Student/djangoproject/myvenv/lib/python3.5/site-packages/django/template/loader.py", line 62, in render_to_string
    return template.render(context, request)
  File "/home/Student/djangoproject/myvenv/lib/python3.5/site-packages/django/template/backends/django.py", line 61, in render
    return self.template.render(context)
  File "/home/Student/djangoproject/myvenv/lib/python3.5/site-packages/django/template/base.py", line 171, in render
    return self._render(context)
  File "/home/Student/djangoproject/myvenv/lib/python3.5/site-packages/django/template/base.py", line 163, in _render
    return self.nodelist.render(context)
  File "/home/Student/djangoproject/myvenv/lib/python3.5/site-packages/django/template/base.py", line 937, in render
    bit = node.render_annotated(context)
  File "/home/Student/djangoproject/myvenv/lib/python3.5/site-packages/django/template/base.py", line 904, in render_annotated
    return self.render(context)
  File "/home/Student/djangoproject/myvenv/lib/python3.5/site-packages/django/template/defaulttags.py", line 209, in render
    nodelist.append(node.render_annotated(context))
  File "/home/Student/djangoproject/myvenv/lib/python3.5/site-packages/django/template/base.py", line 904, in render_annotated
    return self.render(context)
  File "/home/Student/djangoproject/myvenv/lib/python3.5/site-packages/django/template/defaulttags.py", line 165, in render
    values = list(values)
TypeError: 'RelatedManager' object is not iterable
2020/04/01 21:00:48 ERROR [django.request:11430:Internal Server Error: /django/just_url/]
Traceback (most recent call last):
  File "/home/Student/djangoproject/myvenv/lib/python3.5/site-packages/django/db/backends/utils.py", line 84, in _execute
    return self.cursor.execute(sql, params)
psycopg2.errors.NotNullViolation: null value in column "comment_book_id" violates not-null constraint
DETAIL:  Failing row contains (7, hello, null).


The above exception was the direct cause of the following exception:

Traceback (most recent call last):
  File "/home/Student/djangoproject/myvenv/lib/python3.5/site-packages/django/core/handlers/exception.py", line 34, in inner
    response = get_response(request)
  File "/home/Student/djangoproject/myvenv/lib/python3.5/site-packages/django/core/handlers/base.py", line 115, in _get_response
    response = self.process_exception_by_middleware(e, request)
  File "/home/Student/djangoproject/myvenv/lib/python3.5/site-packages/django/core/handlers/base.py", line 113, in _get_response
    response = wrapped_callback(request, *callback_args, **callback_kwargs)
  File "/home/Student/djangoproject/bestproject/bookshop/views.py", line 25, in comment_handler
    form.save()
  File "/home/Student/djangoproject/myvenv/lib/python3.5/site-packages/django/forms/models.py", line 458, in save
    self.instance.save()
  File "/home/Student/djangoproject/myvenv/lib/python3.5/site-packages/django/db/models/base.py", line 741, in save
    force_update=force_update, update_fields=update_fields)
  File "/home/Student/djangoproject/myvenv/lib/python3.5/site-packages/django/db/models/base.py", line 779, in save_base
    force_update, using, update_fields,
  File "/home/Student/djangoproject/myvenv/lib/python3.5/site-packages/django/db/models/base.py", line 870, in _save_table
    result = self._do_insert(cls._base_manager, using, fields, update_pk, raw)
  File "/home/Student/djangoproject/myvenv/lib/python3.5/site-packages/django/db/models/base.py", line 908, in _do_insert
    using=using, raw=raw)
  File "/home/Student/djangoproject/myvenv/lib/python3.5/site-packages/django/db/models/manager.py", line 82, in manager_method
    return getattr(self.get_queryset(), name)(*args, **kwargs)
  File "/home/Student/djangoproject/myvenv/lib/python3.5/site-packages/django/db/models/query.py", line 1186, in _insert
    return query.get_compiler(using=using).execute_sql(return_id)
  File "/home/Student/djangoproject/myvenv/lib/python3.5/site-packages/django/db/models/sql/compiler.py", line 1375, in execute_sql
    cursor.execute(sql, params)
  File "/home/Student/djangoproject/myvenv/lib/python3.5/site-packages/django/db/backends/utils.py", line 67, in execute
    return self._execute_with_wrappers(sql, params, many=False, executor=self._execute)
  File "/home/Student/djangoproject/myvenv/lib/python3.5/site-packages/django/db/backends/utils.py", line 76, in _execute_with_wrappers
    return executor(sql, params, many, context)
  File "/home/Student/djangoproject/myvenv/lib/python3.5/site-packages/django/db/backends/utils.py", line 84, in _execute
    return self.cursor.execute(sql, params)
  File "/home/Student/djangoproject/myvenv/lib/python3.5/site-packages/django/db/utils.py", line 89, in __exit__
    raise dj_exc_value.with_traceback(traceback) from exc_value
  File "/home/Student/djangoproject/myvenv/lib/python3.5/site-packages/django/db/backends/utils.py", line 84, in _execute
    return self.cursor.execute(sql, params)
django.db.utils.IntegrityError: null value in column "comment_book_id" violates not-null constraint
DETAIL:  Failing row contains (7, hello, null).

2020/04/01 21:25:56 ERROR [django.request:11893:Internal Server Error: /django/just_url/3/]
Traceback (most recent call last):
  File "/home/Student/djangoproject/myvenv/lib/python3.5/site-packages/django/core/handlers/exception.py", line 34, in inner
    response = get_response(request)
  File "/home/Student/djangoproject/myvenv/lib/python3.5/site-packages/django/core/handlers/base.py", line 115, in _get_response
    response = self.process_exception_by_middleware(e, request)
  File "/home/Student/djangoproject/myvenv/lib/python3.5/site-packages/django/core/handlers/base.py", line 113, in _get_response
    response = wrapped_callback(request, *callback_args, **callback_kwargs)
  File "/home/Student/djangoproject/bestproject/bookshop/views.py", line 27, in comment_handler
    form.save(comment_book_id=id_book)
TypeError: save() got an unexpected keyword argument 'comment_book_id'
2020/04/01 21:29:08 ERROR [django.request:11974:Internal Server Error: /django/just_url/3/]
Traceback (most recent call last):
  File "/home/Student/djangoproject/myvenv/lib/python3.5/site-packages/django/core/handlers/exception.py", line 34, in inner
    response = get_response(request)
  File "/home/Student/djangoproject/myvenv/lib/python3.5/site-packages/django/core/handlers/base.py", line 115, in _get_response
    response = self.process_exception_by_middleware(e, request)
  File "/home/Student/djangoproject/myvenv/lib/python3.5/site-packages/django/core/handlers/base.py", line 113, in _get_response
    response = wrapped_callback(request, *callback_args, **callback_kwargs)
  File "/home/Student/djangoproject/bestproject/bookshop/views.py", line 27, in comment_handler
    form.save(comment_book=id_book)
TypeError: save() got an unexpected keyword argument 'comment_book'
2020/04/01 21:38:44 INFO [django.utils.autoreload:12203:Watching for file changes with StatReloader]
2020/04/01 21:38:51 INFO [django.server:12203:"GET /world/ HTTP/1.0" 200 1978]
2020/04/01 21:38:55 INFO [django.server:12203:"POST /just_url/1/ HTTP/1.0" 302 0]
2020/04/01 21:38:55 INFO [django.server:12203:"GET /world/ HTTP/1.0" 200 1978]
2020/04/01 21:40:17 INFO [django.utils.autoreload:12203:/home/Student/djangoproject/bestproject/bookshop/views.py changed, reloading.]
2020/04/01 21:40:17 INFO [django.utils.autoreload:12242:Watching for file changes with StatReloader]
2020/04/01 21:40:34 INFO [django.utils.autoreload:12242:/home/Student/djangoproject/bestproject/bookshop/views.py changed, reloading.]
2020/04/01 21:40:34 INFO [django.utils.autoreload:12246:Watching for file changes with StatReloader]
2020/04/01 21:40:41 ERROR [django.request:12246:Internal Server Error: /django/just_url/1/]
Traceback (most recent call last):
  File "/usr/local/lib/python3.5/dist-packages/django/core/handlers/exception.py", line 34, in inner
    response = get_response(request)
  File "/usr/local/lib/python3.5/dist-packages/django/core/handlers/base.py", line 115, in _get_response
    response = self.process_exception_by_middleware(e, request)
  File "/usr/local/lib/python3.5/dist-packages/django/core/handlers/base.py", line 113, in _get_response
    response = wrapped_callback(request, *callback_args, **callback_kwargs)
  File "/home/Student/djangoproject/bestproject/bookshop/views.py", line 28, in comment_handler
    if form.is_valid():
  File "/usr/local/lib/python3.5/dist-packages/django/forms/forms.py", line 185, in is_valid
    return self.is_bound and not self.errors
  File "/usr/local/lib/python3.5/dist-packages/django/forms/forms.py", line 180, in errors
    self.full_clean()
  File "/usr/local/lib/python3.5/dist-packages/django/forms/forms.py", line 381, in full_clean
    self._clean_fields()
  File "/usr/local/lib/python3.5/dist-packages/django/forms/forms.py", line 390, in _clean_fields
    if field.disabled:
AttributeError: 'str' object has no attribute 'disabled'
2020/04/01 21:40:41 ERROR [django.server:12246:"POST /just_url/1/ HTTP/1.0" 500 27]
2020/04/01 21:43:31 INFO [django.utils.autoreload:12246:/home/Student/djangoproject/bestproject/bookshop/views.py changed, reloading.]
2020/04/01 21:43:32 INFO [django.utils.autoreload:12284:Watching for file changes with StatReloader]
2020/04/01 21:43:51 ERROR [django.request:12284:Internal Server Error: /django/just_url/1/]
Traceback (most recent call last):
  File "/usr/local/lib/python3.5/dist-packages/django/core/handlers/exception.py", line 34, in inner
    response = get_response(request)
  File "/usr/local/lib/python3.5/dist-packages/django/core/handlers/base.py", line 115, in _get_response
    response = self.process_exception_by_middleware(e, request)
  File "/usr/local/lib/python3.5/dist-packages/django/core/handlers/base.py", line 113, in _get_response
    response = wrapped_callback(request, *callback_args, **callback_kwargs)
  File "/home/Student/djangoproject/bestproject/bookshop/views.py", line 28, in comment_handler
    if form.is_valid():
  File "/usr/local/lib/python3.5/dist-packages/django/forms/forms.py", line 185, in is_valid
    return self.is_bound and not self.errors
  File "/usr/local/lib/python3.5/dist-packages/django/forms/forms.py", line 180, in errors
    self.full_clean()
  File "/usr/local/lib/python3.5/dist-packages/django/forms/forms.py", line 381, in full_clean
    self._clean_fields()
  File "/usr/local/lib/python3.5/dist-packages/django/forms/forms.py", line 390, in _clean_fields
    if field.disabled:
AttributeError: 'Book' object has no attribute 'disabled'
2020/04/01 21:43:51 ERROR [django.server:12284:"POST /just_url/1/ HTTP/1.0" 500 27]
2020/04/01 21:44:21 INFO [django.utils.autoreload:12284:/home/Student/djangoproject/bestproject/bookshop/views.py changed, reloading.]
2020/04/01 21:44:21 INFO [django.utils.autoreload:12305:Watching for file changes with StatReloader]
2020/04/01 21:44:26 ERROR [django.request:12305:Internal Server Error: /django/just_url/1/]
Traceback (most recent call last):
  File "/usr/local/lib/python3.5/dist-packages/django/db/backends/utils.py", line 84, in _execute
    return self.cursor.execute(sql, params)
psycopg2.errors.NotNullViolation: null value in column "comment_book_id" violates not-null constraint
DETAIL:  Failing row contains (8, dfgfgdfg, null).


The above exception was the direct cause of the following exception:

Traceback (most recent call last):
  File "/usr/local/lib/python3.5/dist-packages/django/core/handlers/exception.py", line 34, in inner
    response = get_response(request)
  File "/usr/local/lib/python3.5/dist-packages/django/core/handlers/base.py", line 115, in _get_response
    response = self.process_exception_by_middleware(e, request)
  File "/usr/local/lib/python3.5/dist-packages/django/core/handlers/base.py", line 113, in _get_response
    response = wrapped_callback(request, *callback_args, **callback_kwargs)
  File "/home/Student/djangoproject/bestproject/bookshop/views.py", line 29, in comment_handler
    form.save()
  File "/usr/local/lib/python3.5/dist-packages/django/forms/models.py", line 458, in save
    self.instance.save()
  File "/usr/local/lib/python3.5/dist-packages/django/db/models/base.py", line 741, in save
    force_update=force_update, update_fields=update_fields)
  File "/usr/local/lib/python3.5/dist-packages/django/db/models/base.py", line 779, in save_base
    force_update, using, update_fields,
  File "/usr/local/lib/python3.5/dist-packages/django/db/models/base.py", line 870, in _save_table
    result = self._do_insert(cls._base_manager, using, fields, update_pk, raw)
  File "/usr/local/lib/python3.5/dist-packages/django/db/models/base.py", line 908, in _do_insert
    using=using, raw=raw)
  File "/usr/local/lib/python3.5/dist-packages/django/db/models/manager.py", line 82, in manager_method
    return getattr(self.get_queryset(), name)(*args, **kwargs)
  File "/usr/local/lib/python3.5/dist-packages/django/db/models/query.py", line 1186, in _insert
    return query.get_compiler(using=using).execute_sql(return_id)
  File "/usr/local/lib/python3.5/dist-packages/django/db/models/sql/compiler.py", line 1375, in execute_sql
    cursor.execute(sql, params)
  File "/usr/local/lib/python3.5/dist-packages/django/db/backends/utils.py", line 67, in execute
    return self._execute_with_wrappers(sql, params, many=False, executor=self._execute)
  File "/usr/local/lib/python3.5/dist-packages/django/db/backends/utils.py", line 76, in _execute_with_wrappers
    return executor(sql, params, many, context)
  File "/usr/local/lib/python3.5/dist-packages/django/db/backends/utils.py", line 84, in _execute
    return self.cursor.execute(sql, params)
  File "/usr/local/lib/python3.5/dist-packages/django/db/utils.py", line 89, in __exit__
    raise dj_exc_value.with_traceback(traceback) from exc_value
  File "/usr/local/lib/python3.5/dist-packages/django/db/backends/utils.py", line 84, in _execute
    return self.cursor.execute(sql, params)
django.db.utils.IntegrityError: null value in column "comment_book_id" violates not-null constraint
DETAIL:  Failing row contains (8, dfgfgdfg, null).

2020/04/01 21:44:26 ERROR [django.server:12305:"POST /just_url/1/ HTTP/1.0" 500 27]
2020/04/01 21:44:31 ERROR [django.request:12305:Internal Server Error: /django/just_url/1/]
Traceback (most recent call last):
  File "/usr/local/lib/python3.5/dist-packages/django/db/backends/utils.py", line 84, in _execute
    return self.cursor.execute(sql, params)
psycopg2.errors.NotNullViolation: null value in column "comment_book_id" violates not-null constraint
DETAIL:  Failing row contains (9, dfgfgdfg, null).


The above exception was the direct cause of the following exception:

Traceback (most recent call last):
  File "/usr/local/lib/python3.5/dist-packages/django/core/handlers/exception.py", line 34, in inner
    response = get_response(request)
  File "/usr/local/lib/python3.5/dist-packages/django/core/handlers/base.py", line 115, in _get_response
    response = self.process_exception_by_middleware(e, request)
  File "/usr/local/lib/python3.5/dist-packages/django/core/handlers/base.py", line 113, in _get_response
    response = wrapped_callback(request, *callback_args, **callback_kwargs)
  File "/home/Student/djangoproject/bestproject/bookshop/views.py", line 29, in comment_handler
    form.save()
  File "/usr/local/lib/python3.5/dist-packages/django/forms/models.py", line 458, in save
    self.instance.save()
  File "/usr/local/lib/python3.5/dist-packages/django/db/models/base.py", line 741, in save
    force_update=force_update, update_fields=update_fields)
  File "/usr/local/lib/python3.5/dist-packages/django/db/models/base.py", line 779, in save_base
    force_update, using, update_fields,
  File "/usr/local/lib/python3.5/dist-packages/django/db/models/base.py", line 870, in _save_table
    result = self._do_insert(cls._base_manager, using, fields, update_pk, raw)
  File "/usr/local/lib/python3.5/dist-packages/django/db/models/base.py", line 908, in _do_insert
    using=using, raw=raw)
  File "/usr/local/lib/python3.5/dist-packages/django/db/models/manager.py", line 82, in manager_method
    return getattr(self.get_queryset(), name)(*args, **kwargs)
  File "/usr/local/lib/python3.5/dist-packages/django/db/models/query.py", line 1186, in _insert
    return query.get_compiler(using=using).execute_sql(return_id)
  File "/usr/local/lib/python3.5/dist-packages/django/db/models/sql/compiler.py", line 1375, in execute_sql
    cursor.execute(sql, params)
  File "/usr/local/lib/python3.5/dist-packages/django/db/backends/utils.py", line 67, in execute
    return self._execute_with_wrappers(sql, params, many=False, executor=self._execute)
  File "/usr/local/lib/python3.5/dist-packages/django/db/backends/utils.py", line 76, in _execute_with_wrappers
    return executor(sql, params, many, context)
  File "/usr/local/lib/python3.5/dist-packages/django/db/backends/utils.py", line 84, in _execute
    return self.cursor.execute(sql, params)
  File "/usr/local/lib/python3.5/dist-packages/django/db/utils.py", line 89, in __exit__
    raise dj_exc_value.with_traceback(traceback) from exc_value
  File "/usr/local/lib/python3.5/dist-packages/django/db/backends/utils.py", line 84, in _execute
    return self.cursor.execute(sql, params)
django.db.utils.IntegrityError: null value in column "comment_book_id" violates not-null constraint
DETAIL:  Failing row contains (9, dfgfgdfg, null).

2020/04/01 21:44:31 ERROR [django.server:12305:"POST /just_url/1/ HTTP/1.0" 500 27]
2020/04/01 21:47:24 INFO [django.utils.autoreload:12305:/home/Student/djangoproject/bestproject/bookshop/views.py changed, reloading.]
2020/04/01 21:47:25 INFO [django.utils.autoreload:12348:Watching for file changes with StatReloader]
2020/04/01 21:47:48 INFO [django.utils.autoreload:12348:/home/Student/djangoproject/bestproject/bookshop/views.py changed, reloading.]
2020/04/01 21:47:48 INFO [django.utils.autoreload:12365:Watching for file changes with StatReloader]
2020/04/01 21:47:58 ERROR [django:12365:hello error]
2020/04/01 21:47:58 INFO [django.server:12365:"GET / HTTP/1.0" 200 26]
2020/04/01 21:48:01 INFO [django.server:12365:"GET /world/ HTTP/1.0" 200 1978]
2020/04/01 21:48:04 INFO [django.server:12365:"POST /just_url/1/ HTTP/1.0" 302 0]
2020/04/01 21:48:04 INFO [django.server:12365:"GET /world/ HTTP/1.0" 200 2000]
2020/04/01 23:26:54 ERROR [django:12413:hello error]
2020/04/01 23:27:01 WARNING [django.request:12413:Not Found: /django/bookshop]
2020/04/01 23:27:09 WARNING [django.request:12412:Not Found: /django/main]
2020/04/02 22:24:38 ERROR [django:12413:hello error]
2020/04/03 22:15:39 ERROR [django:12412:hello error]
